<?xml version="1.0"?>
<robot name="robot" xmlns:xacro="http://www.ros.org/wiki/xacro">
    <xacro:macro name="wheel" params="side length radius link_xyz link_rpy joint_xyz joint_rpy axis_xyz">
        <link name='wheel_${side}'>
            <visual name='wheel_${side}_visual'>
                <origin xyz="${link_xyz}" rpy="${link_rpy}"/>
                <geometry>
                    <cylinder length="${length}" radius="${radius}"/>
                </geometry>
                <material name="black" />
            </visual>
        </link>

        <joint name="wheel_${side}_joint" type="continuous">
            <origin xyz="${joint_xyz}" rpy="${joint_rpy}"/>
            <child link="wheel_${side}"/>
            <parent link="base_link"/>
            <axis xyz="${axis_xyz}"/>
        </joint>
    </xacro:macro>
</robot>