<?xml version="1.0"?>
<robot name="robot" xmlns:xacro="http://www.ros.org/wiki/xacro">
    <xacro:macro name="sliding_unit" 
                 params="number parent x y z color axis lower_limit upper_limit link_xyz link_rpy joint_xyz joint_rpy">
        <link name='sliding_unit_${number}'>
            <visual>
                <origin xyz="${link_xyz}" rpy="${link_rpy}"/>
                <geometry>
                    <box size="${x} ${y} ${z}"/>
                </geometry>
                <!-- <material name="${color}"/> -->
            </visual>
            <xacro:inertial_box mass="0.05" x="${x}" y="${y}" z="${z}">
                <origin xyz="${link_xyz}" rpy="${link_rpy}"/>
            </xacro:inertial_box>
            <collision>
                <origin xyz="${link_xyz}" rpy="${link_rpy}"/>
                <geometry>
                    <box size="${x} ${y} ${z}"/>
                </geometry>
            </collision>
        </link>

        <joint name="sliding_unit_${number}_joint" type="prismatic">
            <parent link="${parent}"/>
            <child link="sliding_unit_${number}"/>
            <axis xyz="${axis}"/>
            <limit lower='${lower_limit}' upper='${upper_limit}' effort="0" velocity="1"/>
            <origin xyz="${joint_xyz}" rpy="${joint_rpy}"/>
        </joint>
        
    </xacro:macro>
</robot>